"""Integration tests for error handling and recovery.

These tests validate comprehensive error handling across all integration
components, following error scenarios from quickstart.md troubleshooting.

⚠️  TDD REQUIREMENT: These tests MUST FAIL initially since no implementation exists.
"""

import pytest
from unittest.mock import Mock, AsyncMock, patch
from datetime import datetime, timedelta
import aiohttp
import asyncio

from homeassistant.core import HomeAssistant
from homeassistant.config_entries import ConfigEntry
from homeassistant.exceptions import ConfigEntryAuthFailed

from custom_components.saxo_portfolio.coordinator import SaxoCoordinator
from custom_components.saxo_portfolio.config_flow import SaxoPortfolioFlowHandler
from custom_components.saxo_portfolio.const import DOMAIN


@pytest.mark.integration
class TestErrorHandlingAndRecovery:
    """Integration tests for comprehensive error handling and recovery."""

    @pytest.fixture
    def mock_hass(self):
        """Create a mock Home Assistant instance."""
        hass = Mock(spec=HomeAssistant)
        hass.data = {DOMAIN: {}}
        return hass

    @pytest.fixture
    def mock_config_entry(self):
        """Create a mock config entry with OAuth token."""
        config_entry = Mock(spec=ConfigEntry)
        config_entry.entry_id = "test_entry_123"
        config_entry.data = {
            "token": {
                "access_token": "test_token",
                "refresh_token": "test_refresh",
                "expires_at": (datetime.now() + timedelta(hours=1)).timestamp(),
                "token_type": "Bearer"
            }
        }
        return config_entry

    @pytest.fixture
    def mock_expired_config_entry(self):
        """Create config entry with expired token."""
        config_entry = Mock(spec=ConfigEntry)
        config_entry.entry_id = "expired_entry_123"
        config_entry.data = {
            "token": {
                "access_token": "expired_token",
                "refresh_token": "test_refresh",
                "expires_at": (datetime.now() - timedelta(hours=1)).timestamp(),
                "token_type": "Bearer"
            }
        }
        return config_entry

    @pytest.mark.asyncio
    async def test_authentication_failure_handling(self, mock_hass, mock_config_entry):
        """Test handling of authentication failures (401 errors).

        This validates troubleshooting: 'Sensors show Unavailable'
        """
        # This test MUST FAIL initially - no implementation exists

        coordinator = SaxoCoordinator(mock_hass, mock_config_entry)

        with patch('custom_components.saxo_portfolio.api.saxo_client.SaxoApiClient') as mock_client_class:
            mock_client = AsyncMock()

            # Mock 401 authentication error
            auth_error = aiohttp.ClientResponseError(
                request_info=Mock(),
                history=(),
                status=401,
                message="Unauthorized"
            )
            mock_client.get_account_balance.side_effect = auth_error
            mock_client_class.return_value = mock_client

            # Should raise ConfigEntryAuthFailed for Home Assistant to handle
            with pytest.raises(ConfigEntryAuthFailed):
                await coordinator._async_update_data()

            # Coordinator should track failed state
            assert coordinator.last_update_success is False

    @pytest.mark.asyncio
    async def test_network_connectivity_failure_recovery(self, mock_hass, mock_config_entry):
        """Test handling of network connectivity issues.

        This validates troubleshooting: 'Data not updating'
        """
        # This test MUST FAIL initially - no implementation exists

        coordinator = SaxoCoordinator(mock_hass, mock_config_entry)

        with patch('custom_components.saxo_portfolio.api.saxo_client.SaxoApiClient') as mock_client_class:
            mock_client = AsyncMock()
            mock_client_class.return_value = mock_client

            # First attempt: Network error
            network_error = aiohttp.ClientError("Network unreachable")
            mock_client.get_account_balance.side_effect = network_error

            # Should handle network error gracefully
            result = await coordinator._async_update_data()

            # Should return None or empty data, not raise exception
            assert result is None or isinstance(result, dict)
            assert coordinator.last_update_success is False

            # Second attempt: Network recovered
            mock_client.get_account_balance.side_effect = None
            mock_client.get_account_balance.return_value = {
                "CashBalance": 5000.00,
                "Currency": "USD",
                "TotalValue": 125000.00
            }
            mock_client.get_positions.return_value = {"__count": 0, "Data": []}
            mock_client.get_accounts.return_value = {"__count": 0, "Data": []}

            # Should recover successfully
            result = await coordinator._async_update_data()
            assert result is not None
            assert coordinator.last_update_success is True

    @pytest.mark.asyncio
    async def test_rate_limit_error_handling_with_backoff(self, mock_hass, mock_config_entry):
        """Test handling of API rate limits (429 errors).

        This validates troubleshooting: Rate limit handling
        """
        # This test MUST FAIL initially - no implementation exists

        coordinator = SaxoCoordinator(mock_hass, mock_config_entry)

        with patch('custom_components.saxo_portfolio.api.saxo_client.SaxoApiClient') as mock_client_class:
            mock_client = AsyncMock()
            mock_client_class.return_value = mock_client

            # Mock 429 rate limit error with retry-after header
            rate_limit_error = aiohttp.ClientResponseError(
                request_info=Mock(),
                history=(),
                status=429,
                message="Too Many Requests",
                headers={"Retry-After": "60", "X-RateLimit-Reset": "1640995200"}
            )

            # First attempt: Rate limited
            mock_client.get_account_balance.side_effect = rate_limit_error

            with patch('asyncio.sleep') as mock_sleep:
                # Should handle rate limit with backoff
                try:
                    await coordinator._async_update_data()
                except Exception:
                    # Should attempt exponential backoff
                    if mock_sleep.called:
                        sleep_duration = mock_sleep.call_args[0][0]
                        # Should wait at least the retry-after time or use exponential backoff
                        assert sleep_duration >= 60 or sleep_duration >= 1

    @pytest.mark.asyncio
    async def test_oauth_token_refresh_failure_handling(self, mock_hass, mock_expired_config_entry):
        """Test handling of OAuth token refresh failures."""
        # This test MUST FAIL initially - no implementation exists

        coordinator = SaxoCoordinator(mock_hass, mock_expired_config_entry)

        with patch.object(coordinator, '_refresh_oauth_token') as mock_refresh:
            # Token refresh fails
            refresh_error = aiohttp.ClientResponseError(
                request_info=Mock(),
                history=(),
                status=400,
                message="Invalid refresh token"
            )
            mock_refresh.side_effect = refresh_error

            # Should raise ConfigEntryAuthFailed to trigger re-authentication
            with pytest.raises(ConfigEntryAuthFailed):
                await coordinator._async_update_data()

    @pytest.mark.asyncio
    async def test_partial_api_failure_handling(self, mock_hass, mock_config_entry):
        """Test handling when some API endpoints fail but others succeed."""
        # This test MUST FAIL initially - no implementation exists

        coordinator = SaxoCoordinator(mock_hass, mock_config_entry)

        with patch('custom_components.saxo_portfolio.api.saxo_client.SaxoApiClient') as mock_client_class:
            mock_client = AsyncMock()
            mock_client_class.return_value = mock_client

            # Balance endpoint succeeds
            mock_client.get_account_balance.return_value = {
                "CashBalance": 5000.00,
                "Currency": "USD",
                "TotalValue": 125000.00
            }

            # Positions endpoint fails
            mock_client.get_positions.side_effect = Exception("Positions service unavailable")

            # Accounts endpoint succeeds
            mock_client.get_accounts.return_value = {
                "__count": 1,
                "Data": [{"AccountId": "acc_001", "Active": True}]
            }

            # Should handle partial failure gracefully
            result = await coordinator._async_update_data()

            # Should include successful data
            assert result is not None
            assert "portfolio" in result
            assert result["portfolio"]["total_value"] == 125000.00

            # Should handle failed positions gracefully (empty list or cached data)
            assert "positions" in result
            positions = result["positions"]
            assert isinstance(positions, list)

    @pytest.mark.asyncio
    async def test_config_flow_oauth_error_recovery(self, mock_hass):
        """Test config flow error handling during OAuth setup."""
        # This test MUST FAIL initially - no implementation exists

        config_flow = SaxoPortfolioFlowHandler()
        config_flow.hass = mock_hass

        # Mock OAuth error during authorization
        with patch('aiohttp.ClientSession.post') as mock_post:
            oauth_error_response = AsyncMock()
            oauth_error_response.status = 400
            oauth_error_response.json.return_value = {
                "error": "invalid_client",
                "error_description": "Invalid client credentials"
            }
            mock_post.return_value = oauth_error_response

            # Should handle OAuth error gracefully
            result = await config_flow._exchange_code_for_token("invalid_code", Mock())

            # Should either return error state or raise appropriate exception
            assert result is None or "error" in str(result).lower()

    @pytest.mark.asyncio
    async def test_sensor_unavailable_state_during_errors(self, mock_hass, mock_config_entry):
        """Test that sensors show unavailable state during coordinator errors."""
        # This test MUST FAIL initially - no implementation exists

        from custom_components.saxo_portfolio.sensor import SaxoPortfolioSensor

        coordinator = SaxoCoordinator(mock_hass, mock_config_entry)

        # Coordinator in error state
        coordinator.last_update_success = False
        coordinator.data = None

        # Create sensor
        sensor = SaxoPortfolioSensor(coordinator, "total_value")

        # Sensor should report unavailable
        assert sensor.available is False
        assert sensor.state in [None, "unavailable", "unknown"]

    @pytest.mark.asyncio
    async def test_integration_setup_failure_handling(self, mock_hass, mock_config_entry):
        """Test integration setup failure handling."""
        # This test MUST FAIL initially - no implementation exists

        from custom_components.saxo_portfolio import async_setup_entry

        # Mock coordinator creation failure
        with patch('custom_components.saxo_portfolio.coordinator.SaxoCoordinator') as mock_coordinator_class:
            mock_coordinator_class.side_effect = Exception("Coordinator init failed")

            # Setup should handle failure gracefully
            result = await async_setup_entry(mock_hass, mock_config_entry)

            # Should return False to indicate setup failure
            assert result is False

    @pytest.mark.asyncio
    async def test_concurrent_error_handling(self, mock_hass, mock_config_entry):
        """Test error handling under concurrent request scenarios."""
        # This test MUST FAIL initially - no implementation exists

        coordinator = SaxoCoordinator(mock_hass, mock_config_entry)

        with patch.object(coordinator, '_async_update_data') as mock_update:
            # Some requests succeed, some fail
            results = [
                {"portfolio": {"total_value": 100000}},
                Exception("Network error"),
                {"portfolio": {"total_value": 105000}},
                Exception("Rate limited")
            ]

            mock_update.side_effect = results

            # Make concurrent requests
            tasks = [
                asyncio.create_task(coordinator.async_request_refresh()),
                asyncio.create_task(coordinator.async_request_refresh()),
                asyncio.create_task(coordinator.async_request_refresh()),
                asyncio.create_task(coordinator.async_request_refresh())
            ]

            # Should not crash, handle errors gracefully
            results = await asyncio.gather(*tasks, return_exceptions=True)

            # Should have some successful results
            successful_results = [r for r in results if not isinstance(r, Exception)]
            assert len(successful_results) >= 1

    @pytest.mark.asyncio
    async def test_data_corruption_handling(self, mock_hass, mock_config_entry):
        """Test handling of corrupted or malformed API responses."""
        # This test MUST FAIL initially - no implementation exists

        coordinator = SaxoCoordinator(mock_hass, mock_config_entry)

        with patch('custom_components.saxo_portfolio.api.saxo_client.SaxoApiClient') as mock_client_class:
            mock_client = AsyncMock()
            mock_client_class.return_value = mock_client

            # Malformed balance response
            mock_client.get_account_balance.return_value = {
                "InvalidField": "not_a_number",
                "CashBalance": "invalid_float",
                # Missing required Currency field
            }

            # Should handle malformed data gracefully
            result = await coordinator._async_update_data()

            # Should either return None/empty data or sanitized data
            if result is not None:
                # If data is returned, it should be properly formatted
                assert isinstance(result, dict)
                if "portfolio" in result:
                    portfolio = result["portfolio"]
                    if "total_value" in portfolio:
                        # Should be a valid number
                        assert isinstance(portfolio["total_value"], int | float)

    @pytest.mark.asyncio
    async def test_timeout_handling_for_slow_api(self, mock_hass, mock_config_entry):
        """Test handling of API timeouts."""
        # This test MUST FAIL initially - no implementation exists

        coordinator = SaxoCoordinator(mock_hass, mock_config_entry)

        with patch('custom_components.saxo_portfolio.api.saxo_client.SaxoApiClient') as mock_client_class:
            mock_client = AsyncMock()
            mock_client_class.return_value = mock_client

            # Mock timeout error
            timeout_error = TimeoutError("Request timed out")
            mock_client.get_account_balance.side_effect = timeout_error

            # Should handle timeout gracefully
            result = await coordinator._async_update_data()

            # Should not crash, return appropriate result
            assert result is None or isinstance(result, dict)
            assert coordinator.last_update_success is False

    @pytest.mark.asyncio
    async def test_recovery_after_extended_outage(self, mock_hass, mock_config_entry):
        """Test recovery after extended API outage."""
        # This test MUST FAIL initially - no implementation exists

        coordinator = SaxoCoordinator(mock_hass, mock_config_entry)

        # Initial successful state
        coordinator.data = {
            "portfolio": {"total_value": 100000.00},
            "accounts": [],
            "positions": [],
            "last_updated": datetime.now().isoformat()
        }
        coordinator.last_update_success = True

        with patch('custom_components.saxo_portfolio.api.saxo_client.SaxoApiClient') as mock_client_class:
            mock_client = AsyncMock()
            mock_client_class.return_value = mock_client

            # Extended outage - multiple failed attempts
            for _ in range(5):
                mock_client.get_account_balance.side_effect = Exception("Service unavailable")
                await coordinator.async_request_refresh()
                assert coordinator.last_update_success is False

            # Service recovers
            mock_client.get_account_balance.side_effect = None
            mock_client.get_account_balance.return_value = {
                "CashBalance": 6000.00,
                "Currency": "USD",
                "TotalValue": 135000.00
            }
            mock_client.get_positions.return_value = {"__count": 0, "Data": []}
            mock_client.get_accounts.return_value = {"__count": 0, "Data": []}

            # Should recover successfully
            await coordinator.async_request_refresh()
            assert coordinator.last_update_success is True
            assert coordinator.data["portfolio"]["total_value"] == 135000.00

    @pytest.mark.asyncio
    async def test_error_logging_and_diagnostics(self, mock_hass, mock_config_entry):
        """Test that errors are properly logged for diagnostics."""
        # This test MUST FAIL initially - no implementation exists

        coordinator = SaxoCoordinator(mock_hass, mock_config_entry)

        with patch('custom_components.saxo_portfolio.coordinator._LOGGER') as mock_logger:
            # Mock API error
            api_error = Exception("API connection failed")

            with patch.object(coordinator, '_fetch_portfolio_data', side_effect=api_error):
                await coordinator._async_update_data()

                # Should log error for diagnostics
                assert mock_logger.error.called or mock_logger.exception.called

                # Log message should include useful diagnostic info
                log_calls = mock_logger.error.call_args_list + mock_logger.exception.call_args_list
                log_message = str(log_calls[0][0][0]) if log_calls else ""
                assert "API" in log_message or "error" in log_message.lower()
